Workbook

Sheet MAIN
A1: FAN COOL MODEL
A2: < SJ-540 > | B2: Ver. 2014/01/07 | G2: Refrigerant
E3: OK! | G3: R-600a=1,R-134a=2 | H3: 1 | I3: =IF(H3=1,"R-600a",IF(H3=2,"R-134a","??")) -> R-600a | M3: 冷媒 | N3: R-600a
A4: ◇ ＴＥＭＰＡＲＡＴＵＲＥ ◇ | B4: (℃) | D4: ◇HEAT LOAD ◇ | G4: ◇ Compressor Data ◇ | M4: COMP NAME | N4: EGX80CLC 100V 50Hz
A5: F ROOM TF (℃) | B5: -18 | D5: QF TOTAL(kcal/h) (inlet) | E5: =SIZE!E32 -> 27.35818 | G5: COMPRESSOR NAME | H5: =N4 -> EGX80CLC 100V 50Hz | I5: R-600a | M5: Capacity | N5: 181.6
A6: R ROOM TR (℃) | B6: 3 | D6: QR TOTAL(kcal/h) (inlet) | E6: =SIZE!E33+E8 -> 39.405077 | G6: 220/240V 50Hz | M6: COP | N6: 1.77
A7: DP CON. TC (℃) | B7: =B8+E39 -> 40.905515 | D7: QEV TOTAL (kcal/h) (inlet) | E7: =SIZE!E34 -> 5.4330418 | G7: 定格ｺｰﾅｰ | M7: Rpm0= | N7: 2900
A8: OUTSIDE T0 (℃) | B8: 30 | D8: heater (kcal/h) | E8: 0 | G8: N(rpm) | H8: 2900 | J8: Volume Efficiency | M8: Vc= | N8: 11.14 | O8: 回転速度補正
D9: heater (W) | E9: =E8/0.86 -> 0 | G9: Vc(cc) | H9: =N8 -> 11.14 | J9: ηv=(A+B*PC/PE+C*PC)*Kηv | M9: A= | N9: 0.92601423 | O9: a= | P9: 1
A10: ◇ Ｏ Ｔ Ｈ Ｅ Ｒ Ｓ ◇ | D10: Qtotal (=QF+QR+QEV) | E10: =SUM(E5:E7) -> 72.196299 | G10: ηv | H10: =(N9+N10*H14/H15+N11*H14)*K10 -> 0.75782412 | J10: Kηv= | K10: =P9+P10*H8+P11*H8^2 -> 1 | M10: B= | N10: -0.012213123 | O10: b= | P10: 0
A11: FAN TOTAL (m3/h) | B11: =70*B13/3000*(B12/100)^2 -> 59.5 | G11: T IN | H11: 32.2 | M11: C= | N11: -0.0023789273 | O11: c= | P11: 0
A12: FAN Diameter φmm | B12: 100 | D12: ◇ CALCULATION ◇ | G12: TC Cond | H12: 54.4
A13: FAN SPEED (rpm) | B13: 2550 | D13: Fan out air temp T3 (℃) | E13: =E37+E7/B11/B21/B20/E38 -> -20.77633 | G13: TE Evap | H13: -23.3 | J13: R-600a | K13: R-134a | M13: AW= | N13: 135.175 | O13: 回転速度補正
A14: FAN INPUT (W) | B14: 2.1 | D14: R Air Volume MR (m3/h) | E14: =E6/B20/B21/(B6-E13)/E38 -> 8.5663545 | F14: =E14/B11 -> 0.14397235 | G14: Pc (Tcond) | H14: =IF(H3=1,J14,IF(H3=2,K14,"??")) -> 7.8357768 | J14: =EXP(68.322-4401/(H12+273.16)-9.8436*LN(H12+273.16)+0.0127711*(H12+273.16)) -> 7.8357768 | K14: =EXP(104.918-5301.3/(H12+273.16)-16.2481*LN(H12+273.16)+0.0246593*(H12+273.16)) -> 14.992292 | M14: BW= | N14: 2.6366667 | O14: Ka= | P14: 1
A15: DEF. HEATER INPUT (W) | B15: 140 | D15: F Air Volume MF (m3/h) | E15: =B11-E14 -> 50.933645 | G15: Pe (Teva) | H15: =IF(H3=1,J15,IF(H3=2,K15,"??")) -> 0.63991786 | J15: =EXP(68.322-4401/(H13+273.16)-9.8436*LN(H13+273.16)+0.0127711*(H13+273.16)) -> 0.63991786 | K15: =EXP(104.918-5301.3/(H13+273.16)-16.2481*LN(H13+273.16)+0.0246593*(H13+273.16)) -> 1.1713342 | M15: CW= | N15: 0.975 | O15: Kb= | P15: 0
A16: PWB input Comp ON (W) | B16: 2 | D16: QF' (FAN) (kcal/h) | E16: =(B11-E14)*B21*B20*(B5-E13)*E38 -> 27.358179 | G16: Hout (kcal/kg) | H16: =IF(H3=1,J16,IF(H3=2,K16,"??")) -> 174.07927 | J16: =104.5+0.049951*(H11+273.16)+0.00058822*(H11+273.16)^2-249.18*J15/(H11+273.16) -> 174.07927 | K16: =119.36 + 0.023174 *(H11+273.16) + 0.00031297 * (H11+273.16) ^ 2 - 138.07 *K15/ (H11+273.16) -> 155.08959 | M16: DW= | N16: 0.02 | O16: Kc= | P16: 0
A17: PWB input Comp OFF (W) | B17: 1 | D17: QR' (FAN) (kcal/h) | E17: =E14*B20*B21*(B6-E13)*E38 -> 39.405077 | G17: Hin (kcal/kg) | H17: =IF(H3=1,J17,IF(H3=2,K17,"??")) -> 94.323476 | J17: =75.545+0.55731*H11+0.0007088*H11^2+0.0000029408*H11^3 -> 94.323476 | K17: =100.019 + 0.31763 * H11+ 0.00033057 * H11^ 2 + 0.0000035281 *H11^ 3 -> 110.70722 | M17: EW= | N17: 0.016666667
A18: TIMER Period (hr) | B18: 10.5 | D18: QEV' =M*γ*CP*(TEVIN-TEVOUT)*PR | E18: =B11*B21*B20*(E13-E37)*E38 -> 5.4330418 | G18: V(比体積） | H18: =IF(H3=1,J18,IF(H3=2,K18,"??")) -> 0.68600649 | J18: =0.015883+0.001455*(H11+273.16)/J15-7.2936/(H11+273.16)-0.0004645*J15 -> 0.68600649 | K18: =0.01248+0.0008207*(H11+273.16)/K15-4.663/(H11+273.16)-0.0002297*K15 -> 0.21089214
A19: Def. HEATER ON time (min) | B19: 0 | D19: Air Speed in Evaporator (m/sec) | E19: =B11/(B24*B25)/3600*10^6 -> 0.59883253 | G19: G(循環流量) | H19: =H10*H8*60*H9*10^(-6)/H18 -> 2.1412858
A20: DENSITY(Air) γ (kg/m3) | B20: 1.365 | D20: EV INLET Air Temp. T1 (℃) | E20: =(E14*B6+E15*B5)/B11 -> -14.976581
A21: Cp(Air 0℃) (kcal/kg℃) | B21: 0.24 | D21: LOG. MEAN TEMP. DIFF. OF EVA. (℃) | E21: =E10/E23/B33/E38 -> 6.6684767 | G21: Rated capacity | H21: =H19*(H16-H17) -> 170.77994 | I21: kcal/h
D22: SUB CAL. X | E22: =EXP((E20-E37)/E21) -> 2.5612685 | H22: =H21/0.86 -> 198.58133 | I22: W | J22: 入力回転数補正 | N22: TC= | O22: =B7 -> 40.905515
A23: ◇ EVAPORATOR (NALCO) ◇ | D23: EVA Heat transfer α ( kcal/hm2℃) | E23: =12.93*E19^0.415 -> 10.451539 | G23: Rated input(Ｗ） | H23: =K23*(N13+N14*H13+N15*H12+N16*H12*H13+N17*H13^2)*H8/N7 -> 110.47843 | I23: W | J23: Kw= | K23: =P14+P15*H8+P16*H8^2 -> 1 | N23: Te= | O23: =E24 -> -25.265368
A24: EV WIDTH (=30mm*N) (mm) | B24: 460 | D24: EV TEMPRATURE (℃) | E24: =(E20-E22*E37)/(1-E22) -> -25.265368 | G24: COP | H24: =H21/H23/0.86 -> 1.7974669 | I24: W=(AW+BW*TE+CW*TC*TE+DW*TE^2)*Kw*Rpm/Rpm0 | N24: T0= | O24: =B8 -> 30
A25: EV DEPTH (mm) | B25: 60 | D25: QEV''(Ability of Evaporator) (kcal/h) | E25: =E23*B33*E21 -> 122.24962 | N25: Tsub= | O25: =K28 -> 30.905515
A26: EV Tire (段数) | B26: 7 | D26: COMP INPUT | E26: =K32 -> 98.410647 | G26: ◇ Cooling capacity of Refrigerator Condition ◇ | N26: R-600a | O26: R-134a
A27: Pipe Diameter φ mm | B27: 8 | D27: ON Time INPUT | E27: =E26+B14+B16 -> 102.51065 | G27: Pc (Tcond) | H27: =IF(H3=1,N27,IF(H3=2,O27,"??")) -> 5.6023372 | J27: Capi Sub-cool | K27: 10 | M27: Pc= | N27: =EXP(68.322-4401/(O22+273.16)-9.8436*LN(O22+273.16)+0.0127711*(O22+273.16)) -> 5.6023372 | O27: =EXP(104.918-5301.3/(O22+273.16)-16.2481*LN(O22+273.16)+0.0246593*(O22+273.16)) -> 10.622078
A28: Fin Surface 30*60mm/pc | B28: =(28*60-3.146*(B27/2)^2*2)*2/10^6 -> 0.003158656 | D28: Energy consumption kWh/24h | E28: =(E27*E38+(1-E38)*B17)*24/1000+B15*E31*B19/60/1000 -> 1.4627663 | G28: Pe (Teva) | H28: =IF(H3=1,N28,IF(H3=2,O28,"??")) -> 0.58659092 | J28: TC-Sub cool | K28: =B7-K27 -> 30.905515 | M28: Pe= | N28: =EXP(68.322-4401/(O23+273.16)-9.8436*LN(O23+273.16)+0.0127711*(O23+273.16)) -> 0.58659092 | O28: =EXP(104.918-5301.3/(O23+273.16)-16.2481*LN(O23+273.16)+0.0246593*(O23+273.16)) -> 1.0722676
A29: Toatal fin quqntity | B29: =B45 -> 504 | D29: KWH/MONTH | E29: =E28*30 -> 43.882989 | G29: V(m3/kg） | H29: =IF(H3=1,N29,IF(H3=2,O29,"??")) -> 0.74352028 | J29: Hevin | K29: =IF(H3=1,N30,IF(H3=2,O30,"??")) -> 93.532774 | M29: v= | N29: =0.015883+0.001455*(O24+273.16)/N28-7.2936/(O24+273.16)-0.0004645*N28 -> 0.74352028 | O29: =0.01248+0.0008207*(O24+273.16 )/O28-4.663/(O24+273.16)-0.0002297*O28 -> 0.2288872
A30: Fin Surface m2 | B30: =B29*B28 -> 1.5919626 | D30: Qcomp(Ability of Compressor) (kcal/h) | E30: =K31 -> 122.24962 | G30: Volume Efficiency | H30: =(N9+N10*H27/H28+N11*H27)*K10 -> 0.79604314 | J30: Hevout | K30: =IF(H3=1,N31,IF(H3=2,O31,"??")) -> 152.4401 | M30: Hevin= | N30: =75.545+0.55731*O25+0.0007088*O25^2+0.0000029408*O25^3 -> 93.532774 | O30: =100.019+0.31763*O25+0.00033057*O25^2+0.0000035281*O25^ 3 -> 110.25541
A31: Pipe Surface φ8mm | B31: =(3.146*B27*B24)*B26*2/10^6 -> 0.16208192 | D31: How many defrost in a day （Times/24h) | E31: =24/E32 -> 1.349862 | G31: G(kg/h) | H31: =H30*H8*60*H9*10^(-6)/H29 -> 2.0752873 | J31: QCOMP | K31: =H31*(K30-K29) -> 122.24962 | M31: Hevout= | N31: =104.5+0.049951*(O23+273.16)+0.00058822*(O23+273.16)^2-249.18*N28/(O23+273.16) -> 152.4401 | O31: =119.36 + 0.023174 *(O23+273.16) + 0.00031297 * (O23+273.16) ^ 2 - 138.07 *O28/ (O23+273.16) -> 143.74004
A32: Side Plate surface | B32: 0 | D32: Defrosting cycle Hr | E32: =B18/E38 -> 17.779596 | J32: COMP INPUT | K32: =K23*(N13+N14*E24+N15*B7+N16*B7*E24+N17*E24*E24)*H8/N7 -> 98.410647
A33: SURFACE OF EVAPORATOR (m2) | B33: =B30+B31+B32 -> 1.7540445
G34: ◇ Condenser Heat Exchange ◇
A35: ◇ quantity of Evaporator fin ◇ | D35: ◇ ＶＡＲＩＡＢＬＥ ◇ | G35: Ｒ Front | H35: =(0.3405*(B7-B8)+0.03322*(B7-B6))*(SIZE!B8*2+MAIN!B9)/1000 -> 11.237961
A36: Evaporator Fin quantity | B36: 枚数 | D36: Calculate Cond Temp? Yes=1, No=0 | E36: 1 | G36: ＦＲ Partition | H36: =(0.1984*(B7-B8)+0.1219*(B7-B5))*(SIZE!B9-SIZE!B23-SIZE!B24)/1000 -> 6.4475231 | J36: 熱通過率 | K36: 面積 | M36: サイドコン・バックコンの熱通過率
A37: 1 段 | B37: 93 | D37: X1 =EV OUT Temp. T2 (℃) | E37: -21.248301 | G37: Ｆ Front | H37: =(0.3395*(B7-B8)+0.0344*(B7-B6))*(SIZE!B7*2)/1000 -> 5.5070091 | J37: K | K37: S | N37: K | O37: Pipe Pitch
A38: 2 段 | B38: 93 | D38: X2 =RUNNING RATIO PR (％) | E38: 0.59056461 | G38: Sid Condenser | H38: =J38*K38*E39 -> 111.88111 | I38: Side Cond | J38: =N38 -> 5.395 | K38: =(SIZE!B6*(SIZE!B10-30)-(SIZE!B13+SIZE!B12)*SIZE!B11/2)*2/10^6 -> 1.9016 | M38: Side Cond | N38: =(10.57-0.042*O38+0.00005*O38^2) -> 5.395 | O38: 150
A39: 3 段 | B39: 93 | D39: X3 = ⊿T ( TC-T0) | E39: 10.905515 | G39: Back Condenser | H39: =J39*K39*E39 -> 36.162512 | I39: Back Cond | J39: =N39 -> 4.17 | K39: =SIZE!B9*(SIZE!B6-SIZE!B11)/10^6*K40 -> 0.7952 | M39: Back Cond | N39: =(10.57-0.042*O39+0.00005*O39^2) -> 4.17 | O39: 200
A40: 4 段 | B40: 92 | G40: TOTAL QC0ut | H40: =SUM(H35:H39) -> 171.23612 | I40: バックコン放熱効率 | K40: 0.7
...

Sheet SIZE
A1: =MAIN!A1 -> FAN COOL MODEL | E1: PR= | F1: =MAIN!E38 -> 0.59056461 | G1: TF= | H1: =MAIN!B5 -> -18 | I1: T2= | J1: =MAIN!E37 -> -21.248301
A2: =MAIN!A2 -> < SJ-540 > | G2: TR= | H2: =MAIN!B6 -> 3 | I2: Cab Side | J2: =MAIN!I50 -> 33.474602
E3: Comp temp | F3: =50*F1+H4 -> 59.528231 | G3: TC= | H3: =MAIN!B7 -> 40.905515 | I3: Back cab | J3: =MAIN!I51 -> 32.685651
A4: ◇ Ｓ Ｉ Ｚ Ｅ ◇ | B4: (mm) | G4: T0= | H4: =MAIN!B8 -> 30 | I4: Cab Bottom | J4: =(H3-H4)*F1+H4 -> 36.440411
A5: ◇ BASIC SIZE ◇ | D5: ◇ Heat Load ◇ | H5: B=K*S
A6: TOTAL HIGHT H | B6: 1680 | C6: 0 | D6: POSITION | E6: Q(kcal/h) | F6: S(m2) or L(m) | G6: K | H6: B | I6: INSIDE TEMP | J6: OUTSIDE TEMP
A7: F HIGHT Hf | B7: 550 | D7: F TOP | E7: =H7*(J7-I7) -> 4.8599299 | F7: =(B$9-(B$18+B$19)/2)*(B10-B$22/2)*10^(-6) -> 0.44436 | G7: =1/(1/B$40+1/B$41+B17/1000/(B$34+0.00011*(I7+J7)/2)) -> 0.2278525 | H7: =G7*F7 -> 0.10124854 | I7: =H1 -> -18 | J7: =H4 -> 30
A8: R HIGHT Hr | B8: =B6-B7 -> 1130 | D8: F LEFT | E8: =H8*(J8-I8) -> 3.4576435 | F8: =(B10-B22/2)*(B7-(B17+B20)/2)*10^(-6) -> 0.29118 | G8: =1/(1/B$40+1/B$41+B18/1000/(B$34+0.00011*(I8+J8)/2)) -> 0.23068836 | H8: =G8*F8 -> 0.067171837 | I8: =H1 -> -18 | J8: =J2 -> 33.474602
A9: WIDTH W | B9: 800 | D9: F RIGHT | E9: =H9*(J9-I9) -> 3.4576435 | F9: =F8 -> 0.29118 | G9: =1/(1/B$40+1/B$41+B19/1000/(B$34+0.00011*(I9+J9)/2)) -> 0.23068836 | H9: =G9*F9 -> 0.067171837 | I9: =H1 -> -18 | J9: =J2 -> 33.474602
A10: DEPTH D | B10: 630 | D10: F BOTTOM | E10: =H10*(J10-I10) -> 1.6616438 | F10: =(B10-B22/2)*(B9-(B18+B19)/2)*10^(-6) -> 0.44436 | G10: =1/(1/B$41+1/B$41+B20/1000/(B$34+0.00011*(I10+J10)/2)) -> 0.17806709 | H10: =G10*F10 -> 0.079125894 | I10: =H1 -> -18 | J10: =H2 -> 3
A11: BOTOM HIGHT Hb | B11: 260 | D11: F DOOR | E11: =H11*(J11-I11) -> 4.3370357 | F11: =(B7-B14/2-B36*2)*(B9-B36*2)*10^(-6) -> 0.39655 | G11: =1/(1/B$40+1/B$41+B21/1000/(B$34+0.00011*(I11+J11)/2)) -> 0.2278525 | H11: =G11*F11 -> 0.090354911 | I11: =H1 -> -18 | J11: =H4 -> 30
A12: BOTTOM DEPTH Db1 | B12: 210 | D12: F PACKIN | E12: =H12*(J12-I12) -> 4.3344 | F12: =((B7-B36*2)+(B9-B36*2))*2*10^(-3) -> 2.58 | G12: =B37 -> 0.035 | H12: =G12*F12 -> 0.0903 | I12: =H1 -> -18 | J12: =H4 -> 30
A13: BOTTOM DEPTH Db2 | B13: 230 | D13: F DPCON1(FR-Partition) | E13: =(0.1219*(H3-H1)*F1+0.1219*((0.1984*H4+0.1219*H1)/(0.1984+0.1219)-H1)*(1-F1))*F13 -> 3.8995521 | F13: =(B9-B18-B19)*10^(-3) -> 0.6812 | G13: * | H13: * | I13: * | J13: *
A14: Door gap of F&R door | B14: 10 | D14: F DPCON2(F-Front) | E14: =(0.0791*(MAIN!B7-MAIN!B5)-0.072*(MAIN!B8-MAIN!B5))*F14*MAIN!E38 -> 1.3503318 | F14: =(B7*2+B9)*10^(-3) -> 1.9 | G14: * | H14: * | I14: * | J14: *
D15: R TOP | E15: =H15*(J15-I15) -> -1.6616438 | F15: =(B$9-(B$18+B$19)/2)*(B10-B$22/2)*10^(-6) -> 0.44436 | G15: =1/(1/B$41+1/B$41+B23/1000/(B$34+0.00011*(I15+J15)/2)) -> 0.17806709 | H15: =G15*F15 -> 0.079125894 | I15: =H2 -> 3 | J15: =H1 -> -18
A16: ◇ THICKNESS OF WALL ◇ | D16: R LEFT | E16: =H16*(J16-I16) -> 6.3852539 | F16: =((B8-(B20+B27)/2)*(B10-B26/2)-((B13+B12)*B11/2))*10^(-6) -> 0.5878 | G16: =1/(1/B$40+1/B$41+B24/1000/(B$34+0.00011*(I16+J16)/2)) -> 0.3564598 | H16: =G16*F16 -> 0.20952707 | I16: =H2 -> 3 | J16: =J2 -> 33.474602
A17: F TOP | B17: 59.4 | D17: R RIGHT | E17: =H17*(J17-I17) -> 6.3852539 | F17: =F16 -> 0.5878 | G17: =1/(1/B$40+1/B$41+B25/1000/(B$34+0.00011*(I17+J17)/2)) -> 0.3564598 | H17: =G17*F17 -> 0.20952707 | I17: =H2 -> 3 | J17: =J2 -> 33.474602
A18: F LEFT | B18: 59.4 | D18: R BACK | E18: =H18*(J18-I18) -> 7.0618375 | F18: =(B8-(B20+B27)/2-B11)*(B9-(B24+B25)/2)*10^(-6) -> 0.6194 | G18: =1/(1/B$40+1/B$41+B26/1000/(B$34+0.00011*(I18+J18)/2)) -> 0.25655992 | H18: =G18*F18 -> 0.15891321 | I18: =H2 -> 3 | J18: =(F3-H4)*F1+H4 -> 47.438328
A19: F RIGHT | B19: 59.4 | D19: R BOTTOM 1 | E19: =H19*(J19-I19) -> 2.6391421 | F19: =(B9-(B24+B25)/2)*B12*10^(-6) -> 0.1596 | G19: =1/(1/B$40+1/B$41+B27/1000/(B$34+0.00011*(I19+J19)/2)) -> 0.37211072 | H19: =G19*F19 -> 0.05938887 | I19: =H2 -> 3 | J19: =J18 -> 47.438328
A20: F BOTTOM ※ | B20: 70 | D20: R BOTTOM 2 | E20: =H20*(J20-I20) -> 3.2771622 | F20: =(B9-(B24+B25)/2)*(SQRT(B11^2+(B13-B12)^2))*10^(-6) -> 0.19818375 | G20: =1/(1/B$40+1/B$41+B28/1000/(B$34+0.00011*(I20+J20)/2)) -> 0.37211072 | H20: =G20*F20 -> 0.073746298 | I20: =H2 -> 3 | J20: =J18 -> 47.438328
A21: F DOOR | B21: 59.4 | D21: R BOTTOM 3 | E21: =H21*(J21-I21) -> 1.663861 | F21: =(B9-(B24+B25)/2)*B13*10^(-6) -> 0.1748 | G21: =1/(1/B$40+1/B$41+B29/1000/(B$34+0.00011*(I21+J21)/2)) -> 0.35254281 | H21: =G21*F21 -> 0.061624483 | I21: =H2 -> 3 | J21: =H4 -> 30
A22: EVA BACK | B22: 60 | D22: R DOOR | E22: =H22*(J22-I22) -> 8.5667902 | F22: =(B9-B43*2)*(B8-B14/2-B43*2)*10^(-6) -> 0.9 | G22: =1/(1/B$40+1/B$41+B30/1000/(B$34+0.00011*(I22+J22)/2)) -> 0.35254281 | H22: =G22*F22 -> 0.31728853 | I22: =H2 -> 3 | J22: =H4 -> 30
A23: R TOP ※ | B23: 70 | D23: R PACKIN | E23: =H23*(J23-I23) -> 3.5343 | F23: =((B8-B36*2)+(B9-B36*2))*2*10^(-3) -> 3.74 | G23: =B37 -> 0.035 | H23: =G23*F23 -> 0.1309 | I23: =H2 -> 3 | J23: =H4 -> 30
A24: R LEFT | B24: 40 | D24: R DPCON(R-Front) | E24: =(0.0546*(MAIN!B7-MAIN!B5)-0.0491*(MAIN!B8-MAIN!B5))*F24*MAIN!E38 -> 1.5531198 | F24: =(B8*2+B9)*10^(-3) -> 3.06 | G24: * | H24: * | I24: * | J24: *
A25: R RIGHT | B25: 40 | D25: PWB Heat LOAD | E25: 0
A26: R BACK | B26: 60 | D26: EVA BACK | E26: =H26*(J26-I26) -> 4.3664821 | F26: =(B9-(B18+B19)/2)*(B7-(B17+B20)/2)*10^(-6) -> 0.35941318 | G26: =1/(1/B$40+1/B$41+B22/1000/(B$34+0.00011*(I26+J26)/2)) -> 0.22525552 | H26: =G26*F26 -> 0.080959803 | I26: =J1 -> -21.248301 | J26: =J3 -> 32.685651
A27: R BOTTOM 1 | B27: 40 | D27: FAN LOAD (FAN INPUT*0.86*Pr） | E27: =MAIN!B14*0.86*MAIN!E38 -> 1.0665597
A28: R BOTTOM 2 | B28: 40 | D28: DEF. HEATER LOAD | E28: =MAIN!B15*0.86*MAIN!B19/60/24 -> 0
A29: R BOTTOM 3 | B29: 40
A30: R DOOR | B30: 40
A32: ◇ Thermal Conductivity ◇ | B32: (kcal/mh℃) | D32: QF TOTAL(kcal/h) (inlet) | E32: =SUM(E7:E14) -> 27.35818
A33: URETANE | B33: 0.0165 | D33: QR TOTAL(kcal/h) (inlet) | E33: =SUM(E15:E25) -> 39.405077
A34: A=X-0.00011*T X= | B34: =B33-0.00011*25 -> 0.01375 | D34: QEVOUT TOTAL(kcal/h) (inlet) | E34: =SUM(E26:E28) -> 5.4330418
A35: PS FORM λ | B35: 0.035 | D35: QEV (=QF+QR+QEVOUT) | E35: =SUM(E32:E34) -> 72.196299
A36: Packing position L mm | B36: 15
A37: PAKKIN | B37: 0.035
A39: ◇ Heat trancefer coefficent ◇ | B39: (kcal/m2h℃)
A40: OUTSIDE | B40: 6
A41: INSIDE | B41: 10
D43: VOLUME:
...
