Workbook
Name No.1: [1]Variables!$B$1
Name RecD: [1]Variables!$B$5
Name room: '[2]プルダウンメニュー(削除不可）'!$B$84:$B$89

Sheet 73, IEC62552.2015 COVER
I4: File No.; | AA4: for only confirmation
B5: Class | I5: Date; | J5: 44308 | AA5: not filing.
C6: Refrigarator-freezer | I6: Dept.; | J6: Global. Ref. Eng. Div./ MA Business Unit
B9: Title | C9: Measurement the volume
M10: Sharp brand Refrigerator - Freezer (Household use only)
B12: Theme
C13: We measure the total volume of model: SJ-PV73K/KW-**, SJ-GV73J/JW-**.
C14: （in accordance with IEC 62552:2015)
B16: Result | N16: (Unit; l / Litter )
C17: SJ-PV73K/KW-**, SJ-GV73J/JW-**
D19: TOTAL VOLUME | R19: in case Round F | T19: Measure － Rated | V19: Measure ／ Rated
D20: compartment | F20: Measurement | H20: Rated Volume | T20: A-B:Difference | V20: A/B：Ratio | Y20: sum of diff. | Z20: diff.(%) | AA20: sum of diff.(%)
D21: Food freezer compartment | F21: ='73, IEC62552.2015'!K9 -> 181.8 | H21: =IF(H$23=ROUND(F$21,0)+ROUND(F$22,0),ROUND(F$21,0),IF($Y$21<$Y$27,ROUND(F$21,0),IF($Y$21=$Y$27,IF($AA$21<$AA$27,ROUND(F$21,0),H$23-ROUND(F$22,0)),H$23-ROUND(F$22,0)))) -> 182 | Q21: =R21=H21 -> TRUE | R21: =ROUND(F21,0) -> 182 | S21: F | T21: =F21-R21 -> -0.2 | V21: =F21/R21 -> 0.9989011 | Y21: =ROUND(ABS(T21)+ABS(T22),1) -> 0.6 | Z21: =ABS(1-V21) -> 0.0010989011 | AA21: =Z21+Z22 -> 0.0021627309
D22: Fresh food compartment | F22: ='73, IEC62552.2015'!K10 -> 376.4 | H22: =IF(H$23=ROUND(F$21,0)+ROUND(F$22,0),ROUND(F$22,0),IF($Y$21<$Y$27,H$23-ROUND(F$21,0),IF($Y$21=$Y$27,IF($AA$21<$AA$27,H$23-ROUND(F$21,0),ROUND(F$22,0)),ROUND(F$22,0)))) -> 376 | Q22: =R22=H22 -> TRUE | R22: =R23-R21 -> 376 | S22: R | T22: =F22-R22 -> 0.4 | V22: =F22/R22 -> 1.0010638 | Z22: =ABS(1-V22) -> 0.0010638298
D23: Total volume | F23: =F21+F22 -> 558.2 | H23: =ROUND(F23,0) -> 558 | Q23: =R23=H23 -> TRUE | R23: =H23 -> 558 | S23: TOTAL | T23: =F23-R23 -> 0.2 | V23: =F23/R23 -> 1.0003584
R25: in case Round R | T25: Measure － Rated | V25: Measure ／ Rated
T26: A-B:Difference | V26: A/B：Ratio
Q27: =R27=H21 -> TRUE | R27: =R29-R28 -> 182 | S27: F | T27: =F21-R27 -> -0.2 | V27: =F21/R27 -> 0.9989011 | Y27: =ROUND(ABS(T27)+ABS(T28),1) -> 0.6 | Z27: =ABS(1-V27) -> 0.0010989011 | AA27: =Z27+Z28 -> 0.0021627309
Q28: =R28=H22 -> TRUE | R28: =ROUND(F22,0) -> 376 | S28: R | T28: =F22-R28 -> 0.4 | V28: =F22/R28 -> 1.0010638 | Z28: =ABS(1-V28) -> 0.0010638298
Q29: =R29=H23 -> TRUE | R29: =H23 -> 558 | S29: TOTAL | T29: =F23-R29 -> 0.2 | V29: =F23/R29 -> 1.0003584
B41: Conclusion | D41: Result of the measured Rated Volume complied with the IEC 62552:2015.
B51: Comment

Sheet 73, IEC62552.2015
D7: PV73K/KW, GV73J/JW TYPE VOLUME | K7: IEC62552:2015
K8: VOLUME
H9: FROZEN FOOD | K9: =K79 -> 181.8
H10: FRESH FOOD | K10: =K183 -> 376.4
H11: TOTAL | K11: =K9+K10 -> 558.2
D13: FROZEN FOOD
C14: NO. | D14: LOCATION | E14: ADD/MINUS | F14: DIMENSION(mm) | I14: VOLUME (L) | K14: IEC62552:2015
E15: Q'ty | F15: WIDTH | G15: HEIGHT | H15: DEPTH | K15: VOLUME
C16: F1 | D16: MAIN 1 | E16: 1 | F16: 630.6 | G16: 405.5 | H16: 462.5 | I16: =(E16*F16*G16*H16)/1000000 -> 118.26509 | K16: =I16 -> 118.26509
C17: F2 | D17: MAIN 2 | E17: 1 | F17: 630.6 | G17: 231.8 | H17: 358.5 | I17: =(E17*F17*G17*H17)/1000000 -> 52.403049 | K17: =I17 -> 52.403049
C18: F3 | D18: MAIN 3 | E18: 1 | F18: 630.6 | G18: 32.4 | H18: 47.1 | I18: =(E18*F18*G18*H18)/1000000 -> 0.96232082 | K18: =I18 -> 0.96232082
C19: F4 | D19: F DOOR LINER | E19: 1 | F19: 647.5 | G19: 604.9 | H19: 19 | I19: =(E19*F19*G19*H19)/1000000 -> 7.4417823 | K19: =I19 -> 7.4417823
C20: F5 | D20: F DOOR LINER TOP GAP | E20: 1 | F20: 664.1 | G20: 8.8 | H20: 5 | I20: =(E20*F20*G20*H20)/1000000 -> 0.0292204 | K20: =I20 -> 0.0292204
C21: F6 | D21: F DOOR LINER CONVEX | E21: -3 | F21: 558.5 | G21: 164.7 | H21: 4 | I21: =(E21*F21*G21*H21)/1000000 -> -1.1038194 | K21: =I21 -> -1.1038194
C22: F7 | D22: C-PART BACK | E22: 1 | F22: 630.6 | G22: 37.5 | H22: 299 | I22: =(E22*F22*G22*H22)/1000000 -> 7.0706025 | K22: =I22 -> 7.0706025
C23: F8 | D23: C-PART SIDE 1 | E23: 2 | F23: 32.8 | G23: 37.5 | H23: 119 | I23: =(E23*F23*G23*H23)/1000000 -> 0.29274 | K23: =I23 -> 0.29274
C24: F9 | D24: C-PART SIDE 2 | E24: 2 | F24: 32.8 | G24: 29.5 | H24: 26.4 | I24: =(E24*F24*G24*H24)/1000000 -> 0.05108928 | K24: =I24 -> 0.05108928
C25: F10 | D25: FAN LOUVER SIDE | E25: 2 | F25: 42 | G25: 439.1 | H25: 12 | I25: =(E25*F25*G25*H25)/1000000 -> 0.4426128 | K25: =I25 -> 0.4426128
C26: F11 | D26: LAMP AREA | E26: 1 | F26: 190.4 | G26: 19 | H26: 32.1 | I26: =(E26*F26*G26*H26)/1000000 -> 0.11612496 | K26: =I26 -> 0.11612496
C27: F12 | D27: FOOD LINER RAIL CONVEX | E27: -4 | F27: 8 | G27: 12 | H27: 468.6 | I27: =(E27*F27*G27*H27)/1000000 -> -0.1799424 | K27: =I27 -> -0.1799424
... C30: F15 | D30: FOOD LINER RAIL CONCAVE | E30: 2 | F30: 6.2 | G30: 47 | H30: 344.7 | I30: =(E30*F30*G30*H30)/1000000 -> 0.20089116 | K30: =I30 -> 0.20089116
C31: F16 | D31: FOOD LINER RAIL CONVEX :2007
C32: F17 | D32: FOOD LINER RAIL CONVEX :2007
C33: F18 | D33: GAP CAB～DOOR | E33: 1 | F33: 681.8 | G33: 646.4 | H33: 17 | I33: =(E33*F33*G33*H33)/1000000 -> 7.4921638 | K33: =I33 -> 7.4921638
E34: -1 | F34: 664.1 | G34: 622.8 | H34: 17 | I34: =(E34*F34*G34*H34)/1000000 -> -7.0312252 | K34: =I34 -> -7.0312252
C35: F19 | D35: GAP CAB～DOOR | E35: 2 | F35: 17.5 | G35: 646.4 | H35: 5.9 | I35: =(E35*F35*G35*H35)/1000000 -> 0.1334816 | K35: =I35 -> 0.1334816
C36: F20 | D36: FAN LOUVER 1 | E36: -1 | F36: 333.6 | G36: 44.3 | H36: 63.5 | I36: =(E36*F36*G36*H36)/1000000 -> -0.93843348 | K36: =I36 -> -0.93843348
C37: F21 | D37: FAN LOUVER 2 :2015 | E37: 1 | F37: 333.6 | G37: 15.6 | H37: 63.5 | I37: =(E37*F37*G37*H37)/1000000 -> 0.33046416 | K37: =I37 -> 0.33046416
C38: F22 | D38: FAN LOUVER 3 :2015 | E38: 1 | F38: 333.6 | G38: 5 | H38: 25.5 | I38: =(E38*F38*G38*H38)/1000000 -> 0.042534 | K38: =I38 -> 0.042534
C39: F23 | D39: FAN LOUVER 4 | E39: -1 | F39: 333.6 | G39: 102.7 | H39: 41.5 | I39: =(E39*F39*G39*H39)/1000000 -> -1.4218199 | K39: =I39 -> -1.4218199
C40: F24 | D40: FAN LOUVER 5 :2015 | E40: 1 | F40: 333.6 | G40: 29.7 | H40: 23 | I40: =(E40*F40*G40*H40)/1000000 -> 0.22788216 | K40: =I40 -> 0.22788216
C41: F25 | D41: FAN LOUVER 6 | E41: -1 | F41: 345.1 | G41: 61.1 | H41: 41.5 | I41: =(E41*F41*G41*H41)/1000000 -> -0.87505282 | K41: =I41 -> -0.87505282
C42: F26 | D42: FAN LOUVER 7 | E42: -1 | F42: 345.1 | G42: 8.2 | H42: 4.2 | I42: =(E42*F42*G42*H42)/1000000 -> -0.011885244 | K42: =I42 -> -0.011885244
C43: F27 | D43: FAN LOUVER 8 | E43: -1 | F43: 345.1 | G43: 12.7 | H43: 11 | I43: =(E43*F43*G43*H43)/1000000 -> -0.04821047 | K43: =I43 -> -0.04821047
C44: F28 | D44: FAN LOUVER 9 | E44: -1 | F44: 345.1 | G44: 19.2 | H44: 22 | I44: =(E44*F44*G44*H44)/1000000 -> -0.14577024 | K44: =I44 -> -0.14577024
C45: F29 | D45: FAN LOUVER 10 | E45: -1 | F45: 345.1 | G45: 152.5 | H45: 8 | I45: =(E45*F45*G45*H45)/1000000 -> -0.421022 | K45: =I45 -> -0.421022
C46: F30 | D46: FAN LOUVER 11 | E46: -1 | F46: 345.1 | G46: 18 | H46: 8.3 | I46: =(E46*F46*G46*H46)/1000000 -> -0.05155794 | K46: =I46 -> -0.05155794
... C51: F35 | D51: FAN LOUVER 16 | E51: -1 | F51: 345.1 | G51: 8.9 | H51: 28 | I51: =(E51*F51*G51*H51)/1000000 -> -0.08599892 | K51: =I51 -> -0.08599892
C52: F36 | D52: FAN LOUVER 17 :2007
C53: F37 | D53: FAN LOUVER 18 | E53: -1 | F53: 540.4 | G53: 36.6 | H53: 28.3 | I53: =(E53*F53*G53*H53)/1000000 -> -0.55973551 | K53: =I53 -> -0.55973551
...

Sheet 73, IEC62552.2007 COVER
I4: File No.; | AA4: for only confirmation
B5: Class | I5: Date; | J5: 44308 | AA5: not filing.
C6: Refrigarator-freezer | I6: Dept.; | J6: Global. Ref. Eng. Div./ MA Business Unit
B9: Title | C9: Measurement the volume
M10: Sharp brand Refrigerator - Freezer (Household use only)
B12: Theme
C13: We measure the gross volume and storage volume of model: SJ-PV73K/KW-**, SJ-GV73J/JW-**.
C14: （in accordance with IEC 62552:2007)
B16: Result | N16: (Unit; l / Litter )
C17: SJ-PV73K/KW-**, SJ-GV73J/JW-**
D19: GROSS VOLUME | R19: Measure － Rated | T19: Measure ／ Rated
D20: compartment | F20: Measurement | H20: Rated Volume | R20: A-B:Difference | T20: A/B：Ratio
D21: Food freezer compartment | F21: ='73, IEC62552 2007'!K9 -> 206.9 | H21: =ROUND(F21,0) -> 207 | Q21: F | R21: =F21-H21 -> -0.1 | T21: =F21/H21 -> 0.99951691
D22: Fresh food compartment | F22: ='73, IEC62552 2007'!K10 -> 393.9 | H22: =ROUND(F22,0) -> 394 | Q22: R | R22: =F22-H22 -> -0.1 | T22: =F22/H22 -> 0.99974619
D23: Total | H23: =H21+H22 -> 601 | Q23: TOTAL | R23: =F21+F22-H23 -> -0.2 | T23: =(F21+F22)/H23 -> 0.99966722
D25: STORAGE VOLUME | R25: Measure － Rated | T25: Measure ／ Rated
D26: compartment | F26: Measurement | H26: Rated Volume | R26: A-B:Difference | T26: A/B：Ratio
D27: Food freezer compartment | F27: ='73, IEC62552 2007'!J9 -> 177.9 | H27: =ROUND(F27,0) -> 178 | Q27: F | R27: =F27-H27 -> -0.1 | T27: =F27/H27 -> 0.9994382
D28: Fresh food compartment | F28: ='73, IEC62552 2007'!J10 -> 373 | H28: =ROUND(F28,0) -> 373 | Q28: R | R28: =F28-H28 -> 0 | T28: =F28/H28 -> 1
D29: Total | H29: =H27+H28 -> 551 | Q29: TOTAL | R29: =F27+F28-H29 -> -0.1 | T29: =(F27+F28)/H29 -> 0.99981851
B41: Conclusion | D41: Result of the measured Rated Volume complied with the IEC 62552:2007.
B51: Comment

Sheet 73, IEC62552 2007
D7: PV73K/KW, GV73J/JW TYPE VOLUME | J7: IEC62552:2007
J8: STORAGE | K8: GROSS
H9: FROZEN FOOD | J9: =J79 -> 177.9 | K9: =K79 -> 206.9
H10: FRESH FOOD | J10: =J183 -> 373 | K10: =K183 -> 393.9
D13: FROZEN FOOD
C14: NO. | D14: LOCATION | E14: ADD/MINUS | F14: DIMENSION(mm) | I14: VOLUME (L) | J14: IEC62552:2007
E15: Q'ty | F15: WIDTH | G15: HEIGHT | H15: DEPTH | J15: STORAGE | K15: GROSS
C16: F1 | D16: MAIN 1 | E16: 1 | F16: 630.6 | G16: 405.5 | H16: 462.5 | I16: =(E16*F16*G16*H16)/1000000 -> 118.26509 | J16: =I16 -> 118.26509 | K16: =I16 -> 118.26509
C17: F2 | D17: MAIN 2 | E17: 1 | F17: 630.6 | G17: 231.8 | H17: 358.5 | I17: =(E17*F17*G17*H17)/1000000 -> 52.403049 | J17: =I17 -> 52.403049 | K17: =I17 -> 52.403049
C18: F3 | D18: MAIN 3 | E18: 1 | F18: 630.6 | G18: 32.4 | H18: 47.1 | I18: =(E18*F18*G18*H18)/1000000 -> 0.96232082 | J18: =I18 -> 0.96232082 | K18: =I18 -> 0.96232082
C19: F4 | D19: F DOOR LINER | E19: 1 | F19: 647.5 | G19: 604.9 | H19: 19 | I19: =(E19*F19*G19*H19)/1000000 -> 7.4417823 | J19: =I19 -> 7.4417823 | K19: =I19 -> 7.4417823
C20: F5 | D20: F DOOR LINER TOP GAP | E20: 1 | F20: 664.1 | G20: 8.8 | H20: 5 | I20: =(E20*F20*G20*H20)/1000000 -> 0.0292204 | J20: =I20 -> 0.0292204 | K20: =I20 -> 0.0292204
C21: F6 | D21: F DOOR LINER CONVEX | E21: -3 | F21: 558.5 | G21: 164.7 | H21: 4 | I21: =(E21*F21*G21*H21)/1000000 -> -1.1038194 | J21: =I21 -> -1.1038194 | K21: =I21 -> -1.1038194
C22: F7 | D22: C-PART BACK | E22: 1 | F22: 630.6 | G22: 37.5 | H22: 299 | I22: =(E22*F22*G22*H22)/1000000 -> 7.0706025 | J22: =I22 -> 7.0706025 | K22: =I22 -> 7.0706025
C23: F8 | D23: C-PART SIDE 1 | E23: 2 | F23: 32.8 | G23: 37.5 | H23: 119 | I23: =(E23*F23*G23*H23)/1000000 -> 0.29274 | J23: =I23 -> 0.29274 | K23: =I23 -> 0.29274
C24: F9 | D24: C-PART SIDE 2 | E24: 2 | F24: 32.8 | G24: 29.5 | H24: 26.4 | I24: =(E24*F24*G24*H24)/1000000 -> 0.05108928 | J24: =I24 -> 0.05108928 | K24: =I24 -> 0.05108928
C25: F10 | D25: FAN LOUVER SIDE | E25: 2 | F25: 42 | G25: 439.1 | H25: 12 | I25: =(E25*F25*G25*H25)/1000000 -> 0.4426128 | J25: =I25 -> 0.4426128 | K25: =I25 -> 0.4426128
C26: F11 | D26: LAMP AREA | E26: 1 | F26: 190.4 | G26: 19 | H26: 32.1 | I26: =(E26*F26*G26*H26)/1000000 -> 0.11612496 | K26: =I26 -> 0.11612496
C27: F12 | D27: FOOD LINER RAIL CONVEX | E27: -4 | F27: 8 | G27: 12 | H27: 468.6 | I27: =(E27*F27*G27*H27)/1000000 -> -0.1799424 | J27: =I27 -> -0.1799424 | K27: =I27 -> -0.1799424
C28: F13 | D28: FOOD LINER RAIL CONVEX | E28: -2 | F28: 10 | G28: 17.2 | H28: 336.3 | I28: =(E28*F28*G28*H28)/1000000 -> -0.1156872 | J28: =I28 -> -0.1156872 | K28: =I28 -> -0.1156872
C29: F14 | D29: FOOD LINER RAIL CONCAVE | E29: 4 | F29: 6.5 | G29: 47 | H29: 425.6 | I29: =(E29*F29*G29*H29)/1000000 -> 0.5200832 | K29: =I29 -> 0.5200832
C30: F15 | D30: FOOD LINER RAIL CONCAVE | E30: 2 | F30: 6.2 | G30: 47 | H30: 344.7 | I30: =(E30*F30*G30*H30)/1000000 -> 0.20089116 | K30: =I30 -> 0.20089116
C31: F16 | D31: FOOD LINER RAIL CONVEX :2007 | E31: -4 | F31: 15.1 | G31: 45.7 | H31: 370.3 | I31: =(E31*F31*G31*H31)/1000000 -> -1.0221317 | J31: =I31 -> -1.0221317
C32: F17 | D32: FOOD LINER RAIL CONVEX :2007 | E32: -2 | F32: 15.4 | G32: 45.7 | H32: 298.6 | I32: =(E32*F32*G32*H32)/1000000 -> -0.42029742 | J32: =I32 -> -0.42029742
C33: F18 | D33: GAP CAB～DOOR | E33: 1 | F33: 681.8 | G33: 646.4 | H33: 17 | I33: =(E33*F33*G33*H33)/1000000 -> 7.4921638 | K33: =I33 -> 7.4921638
E34: -1 | F34: 664.1 | G34: 622.8 | H34: 17 | I34: =(E34*F34*G34*H34)/1000000 -> -7.0312252 | K34: =I34 -> -7.0312252
C35: F19 | D35: GAP CAB～DOOR | E35: 2 | F35: 17.5 | G35: 646.4 | H35: 5.9 | I35: =(E35*F35*G35*H35)/1000000 -> 0.1334816 | K35: =I35 -> 0.1334816
C36: F20 | D36: FAN LOUVER 1 | E36: -1 | F36: 333.6 | G36: 44.3 | H36: 63.5 | I36: =(E36*F36*G36*H36)/1000000 -> -0.93843348 | J36: =I36 -> -0.93843348
C37: F21 | D37: FAN LOUVER 2 :2015
C38: F22 | D38: FAN LOUVER 3 :2015
C39: F23 | D39: FAN LOUVER 4 | E39: -1 | F39: 333.6 | G39: 102.7 | H39: 41.5 | I39: =(E39*F39*G39*H39)/1000000 -> -1.4218199 | J39: =I39 -> -1.4218199
C40: F24 | D40: FAN LOUVER 5 :2015
C41: F25 | D41: FAN LOUVER 6 | E41: -1 | F41: 345.1 | G41: 61.1 | H41: 41.5 | I41: =(E41*F41*G41*H41)/1000000 -> -0.87505282 | J41: =I41 -> -0.87505282
C42: F26 | D42: FAN LOUVER 7 | E42: -1 | F42: 345.1 | G42: 8.2 | H42: 4.2 | I42: =(E42*F42*G42*H42)/1000000 -> -0.011885244 | J42: =I42 -> -0.011885244
C43: F27 | D43: FAN LOUVER 8 | E43: -1 | F43: 345.1 | G43: 12.7 | H43: 11 | I43: =(E43*F43*G43*H43)/1000000 -> -0.04821047 | J43: =I43 -> -0.04821047
C44: F28 | D44: FAN LOUVER 9 | E44: -1 | F44: 345.1 | G44: 19.2 | H44: 22 | I44: =(E44*F44*G44*H44)/1000000 -> -0.14577024 | J44: =I44 -> -0.14577024
C45: F29 | D45: FAN LOUVER 10 | E45: -1 | F45: 345.1 | G45: 152.5 | H45: 8 | I45: =(E45*F45*G45*H45)/1000000 -> -0.421022 | J45: =I45 -> -0.421022
C46: F30 | D46: FAN LOUVER 11 | E46: -1 | F46: 345.1 | G46: 18 | H46: 8.3 | I46: =(E46*F46*G46*H46)/1000000 -> -0.05155794 | J46: =I46 -> -0.05155794
C47: F31 | D47: FAN LOUVER 12 | E47: -1 | F47: 345.1 | G47: 11.2 | H47: 5.3 | I47: =(E47*F47*G47*H47)/1000000 -> -0.020485136 | J47: =I47 -> -0.020485136
C48: F32 | D48: FAN LOUVER 13 | E48: -1 | F48: 345.1 | G48: 19.7 | H48: 27 | I48: =(E48*F48*G48*H48)/1000000 -> -0.18355869 | J48: =I48 -> -0.18355869
...

Sheet SIGN
D1: Ref. Eng. | I1: Standard checked
B2: approved | C2: checked | F2: charge | H2: checked | I2: checked
K8: ③
K9: ②
K10: ①
K11: No. | L11: Date | M11: Revise | N11: Approval
